Workbook

Sheet Comparative
A1: COMPARATIVE STATEMENT OF QUOTATIONS – RFQ (MEDICINES)
A2: Lowest rate per item is highlighted green. Blank = not quoted / NIL. Rates are as quoted per UOM (Muller: "Price Per Pack").
A4: Sr | B4: Item Code | C4: Item (Generic) | D4: Preferred Brands (as per RFQ) | E4: UOM | F4: Qty | G4: Ahsan | I4: Aslam | K4: Jamil | M4: Muller | O4: NMMC | Q4: Platinum | S4: No. of Quotes | T4: Lowest Rate | U4: Lowest Vendor(s) | V4: Value @ Lowest Rate | W4: Remarks
G5: Rate | H5: Quoted Brand | I5: Rate | J5: Quoted Brand | K5: Rate | L5: Quoted Brand | M5: Rate | N5: Quoted Brand | O5: Rate | P5: Quoted Brand | Q5: Rate | R5: Quoted Brand
A6: 1 | B6: 99-98-9120014-12-000-000 | C6: INJECTION-TIRZEPATIDE 15 MG/0.5 ML | D6: TIRZATRIM (MACTER), ZEPTIDE(FEROZSONS), TIRVOX (HORIZON) | E6: EACH | F6: 200 | M6: 5525 | N6: ZEPTIDE(FEROZSONS) | S6: =COUNT(G6,I6,K6,M6,O6,Q6) -> 1 | T6: =IF(S6=0,"",MIN(G6,I6,K6,M6,O6,Q6)) -> 5525 | U6: =IF(S6=0,"No quote",LEFT(IF(AND(ISNUMBER(G6),G6=T6),"Ahsan, ","")&IF(AND(ISNUMBER(I6),I6=T6),"Aslam, ","")&IF(AND(ISNUMBER(K6),K6=T6),"Jamil, ","")&IF(AND(ISNUMBER(M6),M6=T6),"Muller, ","")&IF(AND(ISNUMBER(O6),O6=T6),"NMMC, ","")&IF(AND(ISNUMBER(Q6),Q6=T6),"Platinum, ",""),LEN(IF(AND(ISNUMBER(G6),G6=T6),"Ahsan, ","")&IF(AND(ISNUMBER(I6),I6=T6),"Aslam, ","")&IF(AND(ISNUMBER(K6),K6=T6),"Jamil, ","")&IF(AND(ISNUMBER(M6),M6=T6),"Muller, ","")&IF(AND(ISNUMBER(O6),O6=T6),"NMMC, ","")&IF(AND(ISNUMBER(Q6),Q6=T6),"Platinum, ",""))-2)) -> Muller | V6: =IF(S6=0,"",T6*F6) -> 1105000
A7: 2 | B7: 99-98-9120014-11-000-000 | C7: INJECTION-TIRZEPATIDE 7.5 MG/0.5 ML | D7: TIRZATRIM (MACTER), ZEPTIDE (FEROZSONS), TIRVOX (HORIZON) | E7: EACH | F7: 200 | M7: 4207.5 | N7: ZEPTIDE(FEROZSONS) | S7: =COUNT(G7,I7,K7,M7,O7,Q7) -> 1 | T7: =IF(S7=0,"",MIN(G7,I7,K7,M7,O7,Q7)) -> 4207.5 | U7: =IF(S7=0,"No quote",LEFT(IF(AND(ISNUMBER(G7),G7=T7),"Ahsan, ","")&IF(AND(ISNUMBER(I7),I7=T7),"Aslam, ","")&IF(AND(ISNUMBER(K7),K7=T7),"Jamil, ","")&IF(AND(ISNUMBER(M7),M7=T7),"Muller, ","")&IF(AND(ISNUMBER(O7),O7=T7),"NMMC, ","")&IF(AND(ISNUMBER(Q7),Q7=T7),"Platinum, ",""),LEN(IF(AND(ISNUMBER(G7),G7=T7),"Ahsan, ","")&IF(AND(ISNUMBER(I7),I7=T7),"Aslam, ","")&IF(AND(ISNUMBER(K7),K7=T7),"Jamil, ","")&IF(AND(ISNUMBER(M7),M7=T7),"Muller, ","")&IF(AND(ISNUMBER(O7),O7=T7),"NMMC, ","")&IF(AND(ISNUMBER(Q7),Q7=T7),"Platinum, ",""))-2)) -> Muller | V7: =IF(S7=0,"",T7*F7) -> 841500
A8: 3 | B8: 99-98-9120014-10-000-000 | C8: INJECTION-TIRZEPATIDE 5 MG/0.5 ML | D8: TIRZATRIM(MACTER), ZEPTIDE (FEROZSONS), TIRVOX (HORIZON) | E8: EACH | F8: 100 | M8: 3357.5 | N8: ZEPTIDE(FEROZSONS) | S8: =COUNT(G8,I8,K8,M8,O8,Q8) -> 1 | T8: =IF(S8=0,"",MIN(G8,I8,K8,M8,O8,Q8)) -> 3357.5 | U8: =IF(S8=0,"No quote",LEFT(IF(AND(ISNUMBER(G8),G8=T8),"Ahsan, ","")&IF(AND(ISNUMBER(I8),I8=T8),"Aslam, ","")&IF(AND(ISNUMBER(K8),K8=T8),"Jamil, ","")&IF(AND(ISNUMBER(M8),M8=T8),"Muller, ","")&IF(AND(ISNUMBER(O8),O8=T8),"NMMC, ","")&IF(AND(ISNUMBER(Q8),Q8=T8),"Platinum, ",""),LEN(IF(AND(ISNUMBER(G8),G8=T8),"Ahsan, ","")&IF(AND(ISNUMBER(I8),I8=T8),"Aslam, ","")&IF(AND(ISNUMBER(K8),K8=T8),"Jamil, ","")&IF(AND(ISNUMBER(M8),M8=T8),"Muller, ","")&IF(AND(ISNUMBER(O8),O8=T8),"NMMC, ","")&IF(AND(ISNUMBER(Q8),Q8=T8),"Platinum, ",""))-2)) -> Muller | V8: =IF(S8=0,"",T8*F8) -> 335750
A9: 4 | B9: 99-98-9120014-09-000-000 | C9: INJECTION-TIRZEPATIDE 2.5 MG/0.5 ML | D9: TIRZATRIM (MACTER), ZEPTIDE (FEROZSONS), TIRVOX (HORIZON) | E9: EACH | F9: 100 | M9: 2507.5 | N9: ZEPTIDE(FEROZSONS) | S9: =COUNT(G9,I9,K9,M9,O9,Q9) -> 1 | T9: =IF(S9=0,"",MIN(G9,I9,K9,M9,O9,Q9)) -> 2507.5 | U9: =IF(S9=0,"No quote",LEFT(IF(AND(ISNUMBER(G9),G9=T9),"Ahsan, ","")&IF(AND(ISNUMBER(I9),I9=T9),"Aslam, ","")&IF(AND(ISNUMBER(K9),K9=T9),"Jamil, ","")&IF(AND(ISNUMBER(M9),M9=T9),"Muller, ","")&IF(AND(ISNUMBER(O9),O9=T9),"NMMC, ","")&IF(AND(ISNUMBER(Q9),Q9=T9),"Platinum, ",""),LEN(IF(AND(ISNUMBER(G9),G9=T9),"Ahsan, ","")&IF(AND(ISNUMBER(I9),I9=T9),"Aslam, ","")&IF(AND(ISNUMBER(K9),K9=T9),"Jamil, ","")&IF(AND(ISNUMBER(M9),M9=T9),"Muller, ","")&IF(AND(ISNUMBER(O9),O9=T9),"NMMC, ","")&IF(AND(ISNUMBER(Q9),Q9=T9),"Platinum, ",""))-2)) -> Muller | V9: =IF(S9=0,"",T9*F9) -> 250750
A10: 5 | B10: 99-98-9120027-74-000-000 | C10: SACHET-MONTELUKAST 4 MG | D10: FLOAID (ABBOTT), SOLO (ATCO), MONTIGET (GETZ), LUCAST (OBS/AGP), VENTEK (SEARLE), MYTEKA (HILTON), AEROKAST (BH) | E10: PACKET | F10: 100 | G10: 368.9 | H10: AEROKAST | I10: 348.5 | J10: Bosch | K10: 371.28 | L10: FLOAID 4MG | M10: 403.55 | N10: LUCAST (OBS/AGP) | O10: 326.4 | P10: SOLO 4MG SACHET | S10: =COUNT(G10,I10,K10,M10,O10,Q10) -> 5 | T10: =IF(S10=0,"",MIN(G10,I10,K10,M10,O10,Q10)) -> 326.4 | U10: =IF(S10=0,"No quote",LEFT(IF(AND(ISNUMBER(G10),G10=T10),"Ahsan, ","")&IF(AND(ISNUMBER(I10),I10=T10),"Aslam, ","")&IF(AND(ISNUMBER(K10),K10=T10),"Jamil, ","")&IF(AND(ISNUMBER(M10),M10=T10),"Muller, ","")&IF(AND(ISNUMBER(O10),O10=T10),"NMMC, ","")&IF(AND(ISNUMBER(Q10),Q10=T10),"Platinum, ",""),LEN(IF(AND(ISNUMBER(G10),G10=T10),"Ahsan, ","")&IF(AND(ISNUMBER(I10),I10=T10),"Aslam, ","")&IF(AND(ISNUMBER(K10),K10=T10),"Jamil, ","")&IF(AND(ISNUMBER(M10),M10=T10),"Muller, ","")&IF(AND(ISNUMBER(O10),O10=T10),"NMMC, ","")&IF(AND(ISNUMBER(Q10),Q10=T10),"Platinum, ",""))-2)) -> NMMC | V10: =IF(S10=0,"",T10*F10) -> 32640
A11: 6 | B11: 99-98-9120014-04-000-000 | C11: INJECTION-ONDANSETRON 8 MG | D11: ONSEGET (GETZ), EMESSON (HIGHNOON), ZOFRAN (OBS/AGP), ONTIV (SAMI), ENDTRON (HORIZON), ONSET(PHARMEDIC) | E11: EACH | F11: 100 | I11: 786.25 | J11: Horizon | M11: 212.5 | N11: ZOFRAN (OBS/AGP) | S11: =COUNT(G11,I11,K11,M11,O11,Q11) -> 2 | T11: =IF(S11=0,"",MIN(G11,I11,K11,M11,O11,Q11)) -> 212.5 | U11: =IF(S11=0,"No quote",LEFT(IF(AND(ISNUMBER(G11),G11=T11),"Ahsan, ","")&IF(AND(ISNUMBER(I11),I11=T11),"Aslam, ","")&IF(AND(ISNUMBER(K11),K11=T11),"Jamil, ","")&IF(AND(ISNUMBER(M11),M11=T11),"Muller, ","")&IF(AND(ISNUMBER(O11),O11=T11),"NMMC, ","")&IF(AND(ISNUMBER(Q11),Q11=T11),"Platinum, ",""),LEN(IF(AND(ISNUMBER(G11),G11=T11),"Ahsan, ","")&IF(AND(ISNUMBER(I11),I11=T11),"Aslam, ","")&IF(AND(ISNUMBER(K11),K11=T11),"Jamil, ","")&IF(AND(ISNUMBER(M11),M11=T11),"Muller, ","")&IF(AND(ISNUMBER(O11),O11=T11),"NMMC, ","")&IF(AND(ISNUMBER(Q11),Q11=T11),"Platinum, ",""))-2)) -> Muller | V11: =IF(S11=0,"",T11*F11) -> 21250 | W11: Aslam: pack 5'S
A12: 7 | B12: 99-98-9120020-22-000-000 | C12: TABLET-IVERMECTIN 6 MG | D12: IVERMITE TAB (ATCO) | E12: PACKET | F12: 30 | O12: 345.02 | P12: IVERMITE 6MG TAB | S12: =COUNT(G12,I12,K12,M12,O12,Q12) -> 1 | T12: =IF(S12=0,"",MIN(G12,I12,K12,M12,O12,Q12)) -> 345.02 | U12: =IF(S12=0,"No quote",LEFT(IF(AND(ISNUMBER(G12),G12=T12),"Ahsan, ","")&IF(AND(ISNUMBER(I12),I12=T12),"Aslam, ","")&IF(AND(ISNUMBER(K12),K12=T12),"Jamil, ","")&IF(AND(ISNUMBER(M12),M12=T12),"Muller, ","")&IF(AND(ISNUMBER(O12),O12=T12),"NMMC, ","")&IF(AND(ISNUMBER(Q12),Q12=T12),"Platinum, ",""),LEN(IF(AND(ISNUMBER(G12),G12=T12),"Ahsan, ","")&IF(AND(ISNUMBER(I12),I12=T12),"Aslam, ","")&IF(AND(ISNUMBER(K12),K12=T12),"Jamil, ","")&IF(AND(ISNUMBER(M12),M12=T12),"Muller, ","")&IF(AND(ISNUMBER(O12),O12=T12),"NMMC, ","")&IF(AND(ISNUMBER(Q12),Q12=T12),"Platinum, ",""))-2)) -> NMMC | V12: =IF(S12=0,"",T12*F12) -> 10350.6
A13: 8 | B13: 99-98-9120016-07-000-000 | C13: SYRUP-PARACETAMOL FORTE 120 ML | D13: CALPOL PLUS (GSK), NUBEROL-P FORTE (SEARLE), FEBROL-DS (BH),PANADOL FORTE (HALEON) | E13: EACH | F13: 100 | G13: 80.7 | H13: FEBROL-DS | I13: 115.38 | J13: Haleon | K13: 101.48 | L13: CALPOL 6 PLUS SYRUP | O13: 124.45 | P13: NUBEROL-P FORTE 120ML SYP | S13: =COUNT(G13,I13,K13,M13,O13,Q13) -> 4 | T13: =IF(S13=0,"",MIN(G13,I13,K13,M13,O13,Q13)) -> 80.7 | U13: =IF(S13=0,"No quote",LEFT(IF(AND(ISNUMBER(G13),G13=T13),"Ahsan, ","")&IF(AND(ISNUMBER(I13),I13=T13),"Aslam, ","")&IF(AND(ISNUMBER(K13),K13=T13),"Jamil, ","")&IF(AND(ISNUMBER(M13),M13=T13),"Muller, ","")&IF(AND(ISNUMBER(O13),O13=T13),"NMMC, ","")&IF(AND(ISNUMBER(Q13),Q13=T13),"Platinum, ",""),LEN(IF(AND(ISNUMBER(G13),G13=T13),"Ahsan, ","")&IF(AND(ISNUMBER(I13),I13=T13),"Aslam, ","")&IF(AND(ISNUMBER(K13),K13=T13),"Jamil, ","")&IF(AND(ISNUMBER(M13),M13=T13),"Muller, ","")&IF(AND(ISNUMBER(O13),O13=T13),"NMMC, ","")&IF(AND(ISNUMBER(Q13),Q13=T13),"Platinum, ",""))-2)) -> Ahsan | V13: =IF(S13=0,"",T13*F13) -> 8070
A14: 9 | B14: 99-98-9120023-56-000-000 | C14: OINTMENT-TRIAMCINOLONE 10 GM | D14: KENALOG (GSK), VALOLOG (VALOR) | E14: EACH | F14: 100 | S14: =COUNT(G14,I14,K14,M14,O14,Q14) -> 0 | T14: =IF(S14=0,"",MIN(G14,I14,K14,M14,O14,Q14)) | U14: =IF(S14=0,"No quote",LEFT(IF(AND(ISNUMBER(G14),G14=T14),"Ahsan, ","")&IF(AND(ISNUMBER(I14),I14=T14),"Aslam, ","")&IF(AND(ISNUMBER(K14),K14=T14),"Jamil, ","")&IF(AND(ISNUMBER(M14),M14=T14),"Muller, ","")&IF(AND(ISNUMBER(O14),O14=T14),"NMMC, ","")&IF(AND(ISNUMBER(Q14),Q14=T14),"Platinum, ",""),LEN(IF(AND(ISNUMBER(G14),G14=T14),"Ahsan, ","")&IF(AND(ISNUMBER(I14),I14=T14),"Aslam, ","")&IF(AND(ISNUMBER(K14),K14=T14),"Jamil, ","")&IF(AND(ISNUMBER(M14),M14=T14),"Muller, ","")&IF(AND(ISNUMBER(O14),O14=T14),"NMMC, ","")&IF(AND(ISNUMBER(Q14),Q14=T14),"Platinum, ",""))-2)) -> No quote | V14: =IF(S14=0,"",T14*F14)
A15: 10 | B15: 99-98-9120026-14-000-000 | C15: OINTMENT-FLUTICASONE PROPIONATE WITH MUPIROCIN | D15: CUTIVATE-M (GSK) | E15: EACH | F15: 100 | K15: 301.55 | L15: CUTIVATE OINT | S15: =COUNT(G15,I15,K15,M15,O15,Q15) -> 1 | T15: =IF(S15=0,"",MIN(G15,I15,K15,M15,O15,Q15)) -> 301.55 | U15: =IF(S15=0,"No quote",LEFT(IF(AND(ISNUMBER(G15),G15=T15),"Ahsan, ","")&IF(AND(ISNUMBER(I15),I15=T15),"Aslam, ","")&IF(AND(ISNUMBER(K15),K15=T15),"Jamil, ","")&IF(AND(ISNUMBER(M15),M15=T15),"Muller, ","")&IF(AND(ISNUMBER(O15),O15=T15),"NMMC, ","")&IF(AND(ISNUMBER(Q15),Q15=T15),"Platinum, ",""),LEN(IF(AND(ISNUMBER(G15),G15=T15),"Ahsan, ","")&IF(AND(ISNUMBER(I15),I15=T15),"Aslam, ","")&IF(AND(ISNUMBER(K15),K15=T15),"Jamil, ","")&IF(AND(ISNUMBER(M15),M15=T15),"Muller, ","")&IF(AND(ISNUMBER(O15),O15=T15),"NMMC, ","")&IF(AND(ISNUMBER(Q15),Q15=T15),"Platinum, ",""))-2)) -> Jamil | V15: =IF(S15=0,"",T15*F15) -> 30155
A16: 11 | B16: 99-98-9120013-99-000-000 | C16: INJECTION-PARACETAMOL 100 ML | D16: PROVAS (SAMI), NUBEROL P (SEARLE), OTSUMOL (OTSUKA) | E16: EACH | F16: 200 | G16: 195.5 | H16: PROVAS | I16: 212.5 | J16: Searle | O16: 135 | P16: NUBEROL P 100ML INJ | S16: =COUNT(G16,I16,K16,M16,O16,Q16) -> 3 | T16: =IF(S16=0,"",MIN(G16,I16,K16,M16,O16,Q16)) -> 135 | U16: =IF(S16=0,"No quote",LEFT(IF(AND(ISNUMBER(G16),G16=T16),"Ahsan, ","")&IF(AND(ISNUMBER(I16),I16=T16),"Aslam, ","")&IF(AND(ISNUMBER(K16),K16=T16),"Jamil, ","")&IF(AND(ISNUMBER(M16),M16=T16),"Muller, ","")&IF(AND(ISNUMBER(O16),O16=T16),"NMMC, ","")&IF(AND(ISNUMBER(Q16),Q16=T16),"Platinum, ",""),LEN(IF(AND(ISNUMBER(G16),G16=T16),"Ahsan, ","")&IF(AND(ISNUMBER(I16),I16=T16),"Aslam, ","")&IF(AND(ISNUMBER(K16),K16=T16),"Jamil, ","")&IF(AND(ISNUMBER(M16),M16=T16),"Muller, ","")&IF(AND(ISNUMBER(O16),O16=T16),"NMMC, ","")&IF(AND(ISNUMBER(Q16),Q16=T16),"Platinum, ",""))-2)) -> NMMC | V16: =IF(S16=0,"",T16*F16) -> 27000
A17: 12 | B17: 99-98-9120016-05-000-000 | C17: SYRUP-MULTIVITAMIN WITH CARNITINE & LYSINE 120 ML | D17: VI-DAYLIN L (ABBOTT), TRES ORIX Z (HIGHNOON), LYSOVIT (LCI),LEDERPLEX(LCI) | E17: EACH | F17: 200 | K17: 272 | L17: VIDAYLIN L SYP | O17: 279.898 | P17: TRES ORIX Z 120 ML SYRUP | S17: =COUNT(G17,I17,K17,M17,O17,Q17) -> 2 | T17: =IF(S17=0,"",MIN(G17,I17,K17,M17,O17,Q17)) -> 272 | U17: =IF(S17=0,"No quote",LEFT(IF(AND(ISNUMBER(G17),G17=T17),"Ahsan, ","")&IF(AND(ISNUMBER(I17),I17=T17),"Aslam, ","")&IF(AND(ISNUMBER(K17),K17=T17),"Jamil, ","")&IF(AND(ISNUMBER(M17),M17=T17),"Muller, ","")&IF(AND(ISNUMBER(O17),O17=T17),"NMMC, ","")&IF(AND(ISNUMBER(Q17),Q17=T17),"Platinum, ",""),LEN(IF(AND(ISNUMBER(G17),G17=T17),"Ahsan, ","")&IF(AND(ISNUMBER(I17),I17=T17),"Aslam, ","")&IF(AND(ISNUMBER(K17),K17=T17),"Jamil, ","")&IF(AND(ISNUMBER(M17),M17=T17),"Muller, ","")&IF(AND(ISNUMBER(O17),O17=T17),"NMMC, ","")&IF(AND(ISNUMBER(Q17),Q17=T17),"Platinum, ",""))-2)) -> Jamil | V17: =IF(S17=0,"",T17*F17) -> 54400
A18: 13 | B18: 99-98-9120024-26-000-000 | C18: DROP-NAPHAZOLINE (EYE) | D18: CURINE(SCHAZOO), EYCLEAR(REMINGTON), OPTILLERGE(VEGA), PREFRIN-A(BH) | E18: EACH | F18: 200 | I18: 175.95 | J18: Schazoo | S18: =COUNT(G18,I18,K18,M18,O18,Q18) -> 1 | T18: =IF(S18=0,"",MIN(G18,I18,K18,M18,O18,Q18)) -> 175.95 | U18: =IF(S18=0,"No quote",LEFT(IF(AND(ISNUMBER(G18),G18=T18),"Ahsan, ","")&IF(AND(ISNUMBER(I18),I18=T18),"Aslam, ","")&IF(AND(ISNUMBER(K18),K18=T18),"Jamil, ","")&IF(AND(ISNUMBER(M18),M18=T18),"Muller, ","")&IF(AND(ISNUMBER(O18),O18=T18),"NMMC, ","")&IF(AND(ISNUMBER(Q18),Q18=T18),"Platinum, ",""),LEN(IF(AND(ISNUMBER(G18),G18=T18),"Ahsan, ","")&IF(AND(ISNUMBER(I18),I18=T18),"Aslam, ","")&IF(AND(ISNUMBER(K18),K18=T18),"Jamil, ","")&IF(AND(ISNUMBER(M18),M18=T18),"Muller, ","")&IF(AND(ISNUMBER(O18),O18=T18),"NMMC, ","")&IF(AND(ISNUMBER(Q18),Q18=T18),"Platinum, ",""))-2)) -> Aslam | V18: =IF(S18=0,"",T18*F18) -> 35190
A19: 14 | B19: 99-98-9120020-11-000-000 | C19: TABLET-ERTUGLIFLOZINE WITH METFORMIN 2.5/500 MG | D19: ERTUCO-M (ATCO), ERTAFLOZ-MET (HIGHNOON), ERTAHIL-MET (HILTON) | E19: PACKET | F19: 50 | O19: 316.2 | P19: ERTUCO-M 2.5/500MG TAB | S19: =COUNT(G19,I19,K19,M19,O19,Q19) -> 1 | T19: =IF(S19=0,"",MIN(G19,I19,K19,M19,O19,Q19)) -> 316.2 | U19: =IF(S19=0,"No quote",LEFT(IF(AND(ISNUMBER(G19),G19=T19),"Ahsan, ","")&IF(AND(ISNUMBER(I19),I19=T19),"Aslam, ","")&IF(AND(ISNUMBER(K19),K19=T19),"Jamil, ","")&IF(AND(ISNUMBER(M19),M19=T19),"Muller, ","")&IF(AND(ISNUMBER(O19),O19=T19),"NMMC, ","")&IF(AND(ISNUMBER(Q19),Q19=T19),"Platinum, ",""),LEN(IF(AND(ISNUMBER(G19),G19=T19),"Ahsan, ","")&IF(AND(ISNUMBER(I19),I19=T19),"Aslam, ","")&IF(AND(ISNUMBER(K19),K19=T19),"Jamil, ","")&IF(AND(ISNUMBER(M19),M19=T19),"Muller, ","")&IF(AND(ISNUMBER(O19),O19=T19),"NMMC, ","")&IF(AND(ISNUMBER(Q19),Q19=T19),"Platinum, ",""))-2)) -> NMMC | V19: =IF(S19=0,"",T19*F19) -> 15810
A20: 15 | B20: 99-98-9120011-51-000-000 | C20: CAPSULE-CEFIXIME 400 MG | D20: FIXICEF (ATCO), CEFIGET (GETZ), FIXVAL (GSK), EFIX HIGHNOON), CARICEF (SAMI), CEFSPAN (BH) | E20: PACKET | F20: 300 | G20: 620.5 | H20: CEFSPAN | M20: 403.75 | N20: CINKLARE CAP (AGP) | O20: 355.536 | P20: EFIX 400MG CAPSULE | S20: =COUNT(G20,I20,K20,M20,O20,Q20) -> 3 | T20: =IF(S20=0,"",MIN(G20,I20,K20,M20,O20,Q20)) -> 355.536 | U20: =IF(S20=0,"No quote",LEFT(IF(AND(ISNUMBER(G20),G20=T20),"Ahsan, ","")&IF(AND(ISNUMBER(I20),I20=T20),"Aslam, ","")&IF(AND(ISNUMBER(K20),K20=T20),"Jamil, ","")&IF(AND(ISNUMBER(M20),M20=T20),"Muller, ","")&IF(AND(ISNUMBER(O20),O20=T20),"NMMC, ","")&IF(AND(ISNUMBER(Q20),Q20=T20),"Platinum, ",""),LEN(IF(AND(ISNUMBER(G20),G20=T20),"Ahsan, ","")&IF(AND(ISNUMBER(I20),I20=T20),"Aslam, ","")&IF(AND(ISNUMBER(K20),K20=T20),"Jamil, ","")&IF(AND(ISNUMBER(M20),M20=T20),"Muller, ","")&IF(AND(ISNUMBER(O20),O20=T20),"NMMC, ","")&IF(AND(ISNUMBER(Q20),Q20=T20),"Platinum, ",""))-2)) -> NMMC | V20: =IF(S20=0,"",T20*F20) -> 106660.8
A21: 16 | B21: 99-98-9120016-01-000-000 | C21: SYRUP-CEFIXIME 200 MG 30ML | D21: FIXICEF DS (ATCO), CEFIGET DS (GETZ), EFIX DS (HIGHNOON), CARICEF-DS (SAMI), CEFIM-DS (HILTON), CEFSPAN-DS (BH) | E21: EACH | F21: 1000 | G21: 425.85 | H21: CEFSPAN-DS | M21: 306 | N21: CINKLARE CAP (AGP) | O21: 287.81 | P21: FIXICEF DS 200 MG 30ML SYRUP | S21: =COUNT(G21,I21,K21,M21,O21,Q21) -> 3 | T21: =IF(S21=0,"",MIN(G21,I21,K21,M21,O21,Q21)) -> 287.81 | U21: =IF(S21=0,"No quote",LEFT(IF(AND(ISNUMBER(G21),G21=T21),"Ahsan, ","")&IF(AND(ISNUMBER(I21),I21=T21),"Aslam, ","")&IF(AND(ISNUMBER(K21),K21=T21),"Jamil, ","")&IF(AND(ISNUMBER(M21),M21=T21),"Muller, ","")&IF(AND(ISNUMBER(O21),O21=T21),"NMMC, ","")&IF(AND(ISNUMBER(Q21),Q21=T21),"Platinum, ",""),LEN(IF(AND(ISNUMBER(G21),G21=T21),"Ahsan, ","")&IF(AND(ISNUMBER(I21),I21=T21),"Aslam, ","")&IF(AND(ISNUMBER(K21),K21=T21),"Jamil, ","")&IF(AND(ISNUMBER(M21),M21=T21),"Muller, ","")&IF(AND(ISNUMBER(O21),O21=T21),"NMMC, ","")&IF(AND(ISNUMBER(Q21),Q21=T21),"Platinum, ",""))-2)) -> NMMC | V21: =IF(S21=0,"",T21*F21) -> 287810
A22: 17 | B22: 99-98-9120015-99-000-000 | C22: SYRUP - ONDANSETRON 50 ML | D22: UBKINO (ATCO), EMESSON (HIGHNOON), ONDASET (OBS/AGP), ONTIV (SAMI), XORTRON (MCOLSON) | E22: EACH | F22: 100 | G22: 127.5 | H22: ONTIV | M22: 212.5 | N22: ONDASET (OBS/AGP) | O22: 115.6 | P22: UBKINO 50ML SYRUP | S22: =COUNT(G22,I22,K22,M22,O22,Q22) -> 3 | T22: =IF(S22=0,"",MIN(G22,I22,K22,M22,O22,Q22)) -> 115.6 | U22: =IF(S22=0,"No quote",LEFT(IF(AND(ISNUMBER(G22),G22=T22),"Ahsan, ","")&IF(AND(ISNUMBER(I22),I22=T22),"Aslam, ","")&IF(AND(ISNUMBER(K22),K22=T22),"Jamil, ","")&IF(AND(ISNUMBER(M22),M22=T22),"Muller, ","")&IF(AND(ISNUMBER(O22),O22=T22),"NMMC, ","")&IF(AND(ISNUMBER(Q22),Q22=T22),"Platinum, ",""),LEN(IF(AND(ISNUMBER(G22),G22=T22),"Ahsan, ","")&IF(AND(ISNUMBER(I22),I22=T22),"Aslam, ","")&IF(AND(ISNUMBER(K22),K22=T22),"Jamil, ","")&IF(AND(ISNUMBER(M22),M22=T22),"Muller, ","")&IF(AND(ISNUMBER(O22),O22=T22),"NMMC, ","")&IF(AND(ISNUMBER(Q22),Q22=T22),"Platinum, ",""))-2)) -> NMMC | V22: =IF(S22=0,"",T22*F22) -> 11560
A23: 18 | B23: 99-98-9120015-97-000-000 | C23: SYRUP-AZITHROMYCIN 200 MG 15 ML | D23: AZATCO (ATCO), ZETRO (GETZ), AZIPOS (HIGHNOON), AZOMAX (OBS/AGP), AZITMA (SAMI) | E23: EACH | F23: 500 | G23: 255 | M23: 348.5 | N23: AZOMAX (OBS/AGP) | O23: 164.543 | P23: AZIPOS 200MG 15ML SYRUP | S23: =COUNT(G23,I23,K23,M23,O23,Q23) -> 3 | T23: =IF(S23=0,"",MIN(G23,I23,K23,M23,O23,Q23)) -> 164.543 | U23: =IF(S23=0,"No quote",LEFT(IF(AND(ISNUMBER(G23),G23=T23),"Ahsan, ","")&IF(AND(ISNUMBER(I23),I23=T23),"Aslam, ","")&IF(AND(ISNUMBER(K23),K23=T23),"Jamil, ","")&IF(AND(ISNUMBER(M23),M23=T23),"Muller, ","")&IF(AND(ISNUMBER(O23),O23=T23),"NMMC, ","")&IF(AND(ISNUMBER(Q23),Q23=T23),"Platinum, ",""),LEN(IF(AND(ISNUMBER(G23),G23=T23),"Ahsan, ","")&IF(AND(ISNUMBER(I23),I23=T23),"Aslam, ","")&IF(AND(ISNUMBER(K23),K23=T23),"Jamil, ","")&IF(AND(ISNUMBER(M23),M23=T23),"Muller, ","")&IF(AND(ISNUMBER(O23),O23=T23),"NMMC, ","")&IF(AND(ISNUMBER(Q23),Q23=T23),"Platinum, ",""))-2)) -> NMMC | V23: =IF(S23=0,"",T23*F23) -> 82271.5
A24: 19 | B24: 99-98-9120020-06-000-000 | C24: TABLET-DAPAGLIPFOZIN 10 MG | D24: ATCODAP (ATCO), DAPLYZA (GETZ), DAPLOZ (HIGHNOON), DAPA (HILTON), FORZIGA (MCOLSON) | E24: PACKET | F24: 100 | G24: 1015.75 | H24: DAPA | O24: 294.53 | P24: ATCODAP 10MG TABLET | S24: =COUNT(G24,I24,K24,M24,O24,Q24) -> 2 | T24: =IF(S24=0,"",MIN(G24,I24,K24,M24,O24,Q24)) -> 294.53 | U24: =IF(S24=0,"No quote",LEFT(IF(AND(ISNUMBER(G24),G24=T24),"Ahsan, ","")&IF(AND(ISNUMBER(I24),I24=T24),"Aslam, ","")&IF(AND(ISNUMBER(K24),K24=T24),"Jamil, ","")&IF(AND(ISNUMBER(M24),M24=T24),"Muller, ","")&IF(AND(ISNUMBER(O24),O24=T24),"NMMC, ","")&IF(AND(ISNUMBER(Q24),Q24=T24),"Platinum, ",""),LEN(IF(AND(ISNUMBER(G24),G24=T24),"Ahsan, ","")&IF(AND(ISNUMBER(I24),I24=T24),"Aslam, ","")&IF(AND(ISNUMBER(K24),K24=T24),"Jamil, ","")&IF(AND(ISNUMBER(M24),M24=T24),"Muller, ","")&IF(AND(ISNUMBER(O24),O24=T24),"NMMC, ","")&IF(AND(ISNUMBER(Q24),Q24=T24),"Platinum, ",""))-2)) -> NMMC | V24: =IF(S24=0,"",T24*F24) -> 29453
A25: 20 | B25: 99-98-9120020-04-000-000 | C25: TABLET-MECOBALAMIN 500 MCG | D25: NERVON (GETZ), MOBLO (HIGHNOON), MECOVATE (OBS/AGP), MABIL (SAMI), SEREBAL (SEARLE), METHYCOBAL (HILTON), NEUROMET (MARTIN DOW) | E25: PACKET | F25: 300 | G25: 348.5 | H25: MABIL | M25: 291.04 | N25: MECOVATE (OBS/AGP) | O25: 152.405 | P25: MOBLO 500MCG TABLET | S25: =COUNT(G25,I25,K25,M25,O25,Q25) -> 3 | T25: =IF(S25=0,"",MIN(G25,I25,K25,M25,O25,Q25)) -> 152.405 | U25: =IF(S25=0,"No quote",LEFT(IF(AND(ISNUMBER(G25),G25=T25),"Ahsan, ","")&IF(AND(ISNUMBER(I25),I25=T25),"Aslam, ","")&IF(AND(ISNUMBER(K25),K25=T25),"Jamil, ","")&IF(AND(ISNUMBER(M25),M25=T25),"Muller, ","")&IF(AND(ISNUMBER(O25),O25=T25),"NMMC, ","")&IF(AND(ISNUMBER(Q25),Q25=T25),"Platinum, ",""),LEN(IF(AND(ISNUMBER(G25),G25=T25),"Ahsan, ","")&IF(AND(ISNUMBER(I25),I25=T25),"Aslam, ","")&IF(AND(ISNUMBER(K25),K25=T25),"Jamil, ","")&IF(AND(ISNUMBER(M25),M25=T25),"Muller, ","")&IF(AND(ISNUMBER(O25),O25=T25),"NMMC, ","")&IF(AND(ISNUMBER(Q25),Q25=T25),"Platinum, ",""))-2)) -> NMMC | V25: =IF(S25=0,"",T25*F25) -> 45721.5
A26: 21 | B26: 99-98-9120020-03-000-000 | C26: TABLET-AMLODIPINE WITH VALSARTAN 10/160 MG | D26: DIO PLUS (ATCO), COVAM (GETZ), BIFORGE / (HIGHNOON),EXFORGE (OBS/AGP), NORVASC V (OBS/AGP) | E26: PACKET | F26: 35 | I26: 578 | J26: Horizon | M26: 509.32 | N26: NORVASC V (OBS/AGP) | O26: 387.6 | P26: BIFORGE 10/160MG TABLET | S26: =COUNT(G26,I26,K26,M26,O26,Q26) -> 3 | T26: =IF(S26=0,"",MIN(G26,I26,K26,M26,O26,Q26)) -> 387.6 | U26: =IF(S26=0,"No quote",LEFT(IF(AND(ISNUMBER(G26),G26=T26),"Ahsan, ","")&IF(AND(ISNUMBER(I26),I26=T26),"Aslam, ","")&IF(AND(ISNUMBER(K26),K26=T26),"Jamil, ","")&IF(AND(ISNUMBER(M26),M26=T26),"Muller, ","")&IF(AND(ISNUMBER(O26),O26=T26),"NMMC, ","")&IF(AND(ISNUMBER(Q26),Q26=T26),"Platinum, ",""),LEN(IF(AND(ISNUMBER(G26),G26=T26),"Ahsan, ","")&IF(AND(ISNUMBER(I26),I26=T26),"Aslam, ","")&IF(AND(ISNUMBER(K26),K26=T26),"Jamil, ","")&IF(AND(ISNUMBER(M26),M26=T26),"Muller, ","")&IF(AND(ISNUMBER(O26),O26=T26),"NMMC, ","")&IF(AND(ISNUMBER(Q26),Q26=T26),"Platinum, ",""))-2)) -> NMMC | V26: =IF(S26=0,"",T26*F26) -> 13566
A27: 22 | B27: 99-98-9120019-98-000-000 | C27: TABLET-FEBUXOSTAT 40 MG | D27: URIGUARD (ATCO), ZURIG (GETZ), HILORIC (HIGHNOON), FEBUXIN (OBS/AGP), URIGO (SAMI) | E27: PACKET | F27: 50 | G27: 403.75 | H27: URIGO | M27: 516.757 | N27: FEBSTAT 40MG (PHARMATEC) | O27: 267.75 | P27: HILORIC 40MG TABLET | S27: =COUNT(G27,I27,K27,M27,O27,Q27) -> 3 | T27: =IF(S27=0,"",MIN(G27,I27,K27,M27,O27,Q27)) -> 267.75 | U27: =IF(S27=0,"No quote",LEFT(IF(AND(ISNUMBER(G27),G27=T27),"Ahsan, ","")&IF(AND(ISNUMBER(I27),I27=T27),"Aslam, ","")&IF(AND(ISNUMBER(K27),K27=T27),"Jamil, ","")&IF(AND(ISNUMBER(M27),M27=T27),"Muller, ","")&IF(AND(ISNUMBER(O27),O27=T27),"NMMC, ","")&IF(AND(ISNUMBER(Q27),Q27=T27),"Platinum, ",""),LEN(IF(AND(ISNUMBER(G27),G27=T27),"Ahsan, ","")&IF(AND(ISNUMBER(I27),I27=T27),"Aslam, ","")&IF(AND(ISNUMBER(K27),K27=T27),"Jamil, ","")&IF(AND(ISNUMBER(M27),M27=T27),"Muller, ","")&IF(AND(ISNUMBER(O27),O27=T27),"NMMC, ","")&IF(AND(ISNUMBER(Q27),Q27=T27),"Platinum, ",""))-2)) -> NMMC | V27: =IF(S27=0,"",T27*F27) -> 13387.5
A28: 23 | B28: 99-98-9120019-92-000-000 | C28: TABLET-MONTELUKAST 10 MG | D28: FLOAID (ABBOTT), SOLO (ATCO), MONTIGET (GETZ), MONTIT TAB (HIGHNOON), LUCAST (OBS/AGP),MYTEKA (HILTON), AEROKAST (BH) | E28: PACKET | F28: 1000 | G28: 408 | H28: AEROKAST | I28: 425 | J28: Bosch | K28: 333.2 | L28: FLOAID 10MG TAB | M28: 357 | N28: LUCAST (OBS/AGP) | O28: 306 | P28: SOLO 10MG TABLET | S28: =COUNT(G28,I28,K28,M28,O28,Q28) -> 5 | T28: =IF(S28=0,"",MIN(G28,I28,K28,M28,O28,Q28)) -> 306 | U28: =IF(S28=0,"No quote",LEFT(IF(AND(ISNUMBER(G28),G28=T28),"Ahsan, ","")&IF(AND(ISNUMBER(I28),I28=T28),"Aslam, ","")&IF(AND(ISNUMBER(K28),K28=T28),"Jamil, ","")&IF(AND(ISNUMBER(M28),M28=T28),"Muller, ","")&IF(AND(ISNUMBER(O28),O28=T28),"NMMC, ","")&IF(AND(ISNUMBER(Q28),Q28=T28),"Platinum, ",""),LEN(IF(AND(ISNUMBER(G28),G28=T28),"Ahsan, ","")&IF(AND(ISNUMBER(I28),I28=T28),"Aslam, ","")&IF(AND(ISNUMBER(K28),K28=T28),"Jamil, ","")&IF(AND(ISNUMBER(M28),M28=T28),"Muller, ","")&IF(AND(ISNUMBER(O28),O28=T28),"NMMC, ","")&IF(AND(ISNUMBER(Q28),Q28=T28),"Platinum, ",""))-2)) -> NMMC | V28: =IF(S28=0,"",T28*F28) -> 306000 | W28: Aslam: pack 14's
A29: 24 | B29: 99-98-9120026-13-000-000 | C29: OINTMENT- NEOMYCIN WITH POLYMYXIN-B | D29: BACITRACIN & LIGNOCAINE 18 GM, HEALIT (ATCO), XYLOAID (BH), MYCITRACIN PLUS (LCI), POLYFAX PLUS (GSK) | E29: EACH | F29: 300 | K29: 245.48 | L29: POLYFAX PLUS | M29: 261.8 | N29: MYCITRACIN PLUS (LCI) | O29: 111.69 | P29: HEALIT 18GM OINTMENT | S29: =COUNT(G29,I29,K29,M29,O29,Q29) -> 3 | T29: =IF(S29=0,"",MIN(G29,I29,K29,M29,O29,Q29)) -> 111.69 | U29: =IF(S29=0,"No quote",LEFT(IF(AND(ISNUMBER(G29),G29=T29),"Ahsan, ","")&IF(AND(ISNUMBER(I29),I29=T29),"Aslam, ","")&IF(AND(ISNUMBER(K29),K29=T29),"Jamil, ","")&IF(AND(ISNUMBER(M29),M29=T29),"Muller, ","")&IF(AND(ISNUMBER(O29),O29=T29),"NMMC, ","")&IF(AND(ISNUMBER(Q29),Q29=T29),"Platinum, ",""),LEN(IF(AND(ISNUMBER(G29),G29=T29),"Ahsan, ","")&IF(AND(ISNUMBER(I29),I29=T29),"Aslam, ","")&IF(AND(ISNUMBER(K29),K29=T29),"Jamil, ","")&IF(AND(ISNUMBER(M29),M29=T29),"Muller, ","")&IF(AND(ISNUMBER(O29),O29=T29),"NMMC, ","")&IF(AND(ISNUMBER(Q29),Q29=T29),"Platinum, ",""))-2)) -> NMMC | V29: =IF(S29=0,"",T29*F29) -> 33507
A30: 25 | B30: 99-98-9120019-77-000-000 | C30: TABLET-MULTIVITAMIN TEEN FORMULA | D30: VI-DAYLIN- T (ABBOTT), SURBEX T (ABBOTT), KIDS ONE DAILY (ROUTE 2 HEALTH) | E30: PACKET | F30: 100 | K30: 267.75 | L30: SURBEX T TAB | S30: =COUNT(G30,I30,K30,M30,O30,Q30) -> 1 | T30: =IF(S30=0,"",MIN(G30,I30,K30,M30,O30,Q30)) -> 267.75 | U30: =IF(S30=0,"No quote",LEFT(IF(AND(ISNUMBER(G30),G30=T30),"Ahsan, ","")&IF(AND(ISNUMBER(I30),I30=T30),"Aslam, ","")&IF(AND(ISNUMBER(K30),K30=T30),"Jamil, ","")&IF(AND(ISNUMBER(M30),M30=T30),"Muller, ","")&IF(AND(ISNUMBER(O30),O30=T30),"NMMC, ","")&IF(AND(ISNUMBER(Q30),Q30=T30),"Platinum, ",""),LEN(IF(AND(ISNUMBER(G30),G30=T30),"Ahsan, ","")&IF(AND(ISNUMBER(I30),I30=T30),"Aslam, ","")&IF(AND(ISNUMBER(K30),K30=T30),"Jamil, ","")&IF(AND(ISNUMBER(M30),M30=T30),"Muller, ","")&IF(AND(ISNUMBER(O30),O30=T30),"NMMC, ","")&IF(AND(ISNUMBER(Q30),Q30=T30),"Platinum, ",""))-2)) -> Jamil | V30: =IF(S30=0,"",T30*F30) -> 26775
A31: 26 | B31: 99-98-9120015-92-000-000 | C31: SYRUP-SODIUM ACID CITRATE 150 ML | D31: CITRALKA (LCI), ALKACIT (FEROZSONS) | E31: EACH | F31: 100 | O31: 147.9 | P31: CITRALKA 150ML SYRUP | S31: =COUNT(G31,I31,K31,M31,O31,Q31) -> 1 | T31: =IF(S31=0,"",MIN(G31,I31,K31,M31,O31,Q31)) -> 147.9 | U31: =IF(S31=0,"No quote",LEFT(IF(AND(ISNUMBER(G31),G31=T31),"Ahsan, ","")&IF(AND(ISNUMBER(I31),I31=T31),"Aslam, ","")&IF(AND(ISNUMBER(K31),K31=T31),"Jamil, ","")&IF(AND(ISNUMBER(M31),M31=T31),"Muller, ","")&IF(AND(ISNUMBER(O31),O31=T31),"NMMC, ","")&IF(AND(ISNUMBER(Q31),Q31=T31),"Platinum, ",""),LEN(IF(AND(ISNUMBER(G31),G31=T31),"Ahsan, ","")&IF(AND(ISNUMBER(I31),I31=T31),"Aslam, ","")&IF(AND(ISNUMBER(K31),K31=T31),"Jamil, ","")&IF(AND(ISNUMBER(M31),M31=T31),"Muller, ","")&IF(AND(ISNUMBER(O31),O31=T31),"NMMC, ","")&IF(AND(ISNUMBER(Q31),Q31=T31),"Platinum, ",""))-2)) -> NMMC | V31: =IF(S31=0,"",T31*F31) -> 14790
A32: 27 | B32: 99-98-9120023-53-000-000 | C32: GEL-METRONIDAZOLE 1% WITH CHLORHEXIDINE GLUCONATE 0.25% | D32: REVOMAT PLUS GEL(KAIZEN) | E32: EACH | F32: 100 | Q32: 343.19 | R32: Revomet Plus Gel | S32: =COUNT(G32,I32,K32,M32,O32,Q32) -> 1 | T32: =IF(S32=0,"",MIN(G32,I32,K32,M32,O32,Q32)) -> 343.19 | U32: =IF(S32=0,"No quote",LEFT(IF(AND(ISNUMBER(G32),G32=T32),"Ahsan, ","")&IF(AND(ISNUMBER(I32),I32=T32),"Aslam, ","")&IF(AND(ISNUMBER(K32),K32=T32),"Jamil, ","")&IF(AND(ISNUMBER(M32),M32=T32),"Muller, ","")&IF(AND(ISNUMBER(O32),O32=T32),"NMMC, ","")&IF(AND(ISNUMBER(Q32),Q32=T32),"Platinum, ",""),LEN(IF(AND(ISNUMBER(G32),G32=T32),"Ahsan, ","")&IF(AND(ISNUMBER(I32),I32=T32),"Aslam, ","")&IF(AND(ISNUMBER(K32),K32=T32),"Jamil, ","")&IF(AND(ISNUMBER(M32),M32=T32),"Muller, ","")&IF(AND(ISNUMBER(O32),O32=T32),"NMMC, ","")&IF(AND(ISNUMBER(Q32),Q32=T32),"Platinum, ",""))-2)) -> Platinum | V32: =IF(S32=0,"",T32*F32) -> 34319
A33: 28 | B33: 99-98-9120027-27-000-000 | C33: POWDER-ORS SACHET | D33: OSMOLAR (ATCO), PEDITRAL (ORS), HILYTE-R (HILTON), OEM (INDUS) | E33: PACKET | F33: 2500 | M33: 743.4 | N33: ORTIE SACHET PACK OF 25S (OTSUKA) | O33: 329.73 | P33: OSMOLAR POWDER-ORS SACHET | S33: =COUNT(G33,I33,K33,M33,O33,Q33) -> 2 | T33: =IF(S33=0,"",MIN(G33,I33,K33,M33,O33,Q33)) -> 329.73 | U33: =IF(S33=0,"No quote",LEFT(IF(AND(ISNUMBER(G33),G33=T33),"Ahsan, ","")&IF(AND(ISNUMBER(I33),I33=T33),"Aslam, ","")&IF(AND(ISNUMBER(K33),K33=T33),"Jamil, ","")&IF(AND(ISNUMBER(M33),M33=T33),"Muller, ","")&IF(AND(ISNUMBER(O33),O33=T33),"NMMC, ","")&IF(AND(ISNUMBER(Q33),Q33=T33),"Platinum, ",""),LEN(IF(AND(ISNUMBER(G33),G33=T33),"Ahsan, ","")&IF(AND(ISNUMBER(I33),I33=T33),"Aslam, ","")&IF(AND(ISNUMBER(K33),K33=T33),"Jamil, ","")&IF(AND(ISNUMBER(M33),M33=T33),"Muller, ","")&IF(AND(ISNUMBER(O33),O33=T33),"NMMC, ","")&IF(AND(ISNUMBER(Q33),Q33=T33),"Platinum, ",""))-2)) -> NMMC | V33: =IF(S33=0,"",T33*F33) -> 824325
A34: 29 | B34: 99-98-9120026-03-000-000 | C34: OINTMENT-BETAMETHASONE VALERATE WITH NEOMYCIN 20 GM | D34: BETADERM-N (ATCO), BETNOVATE N (GSK) | E34: EACH | F34: 50 | K34: 153.53 | L34: BETNOVATE N OINT | O34: 102 | P34: BETADERM-N 20GM OINTMENT | S34: =COUNT(G34,I34,K34,M34,O34,Q34) -> 2 | T34: =IF(S34=0,"",MIN(G34,I34,K34,M34,O34,Q34)) -> 102 | U34: =IF(S34=0,"No quote",LEFT(IF(AND(ISNUMBER(G34),G34=T34),"Ahsan, ","")&IF(AND(ISNUMBER(I34),I34=T34),"Aslam, ","")&IF(AND(ISNUMBER(K34),K34=T34),"Jamil, ","")&IF(AND(ISNUMBER(M34),M34=T34),"Muller, ","")&IF(AND(ISNUMBER(O34),O34=T34),"NMMC, ","")&IF(AND(ISNUMBER(Q34),Q34=T34),"Platinum, ",""),LEN(IF(AND(ISNUMBER(G34),G34=T34),"Ahsan, ","")&IF(AND(ISNUMBER(I34),I34=T34),"Aslam, ","")&IF(AND(ISNUMBER(K34),K34=T34),"Jamil, ","")&IF(AND(ISNUMBER(M34),M34=T34),"Muller, ","")&IF(AND(ISNUMBER(O34),O34=T34),"NMMC, ","")&IF(AND(ISNUMBER(Q34),Q34=T34),"Platinum, ",""))-2)) -> NMMC | V34: =IF(S34=0,"",T34*F34) -> 5100
A35: 30 | B35: 99-98-9120023-15-000-000 | C35: CREAM-HYDROCORTISONE WITH CLOTRIMAZOLE 20G | D35: CUREZOLE (ATCO), HYDROZOLE (HALEON), AQUAZOLE (MARTIN DOW) | E35: EACH | F35: 200 | I35: 254.27 | J35: Haleon | K35: 254.29 | L35: HYDROZOLE CREAM | M35: 165.82 | N35: CANESTEN CLOTRIMAZOLE 20GM (BAYER)) | O35: 153.43 | P35: CUREZOLE 20G CREAM | S35: =COUNT(G35,I35,K35,M35,O35,Q35) -> 4 | T35: =IF(S35=0,"",MIN(G35,I35,K35,M35,O35,Q35)) -> 153.43 | U35: =IF(S35=0,"No quote",LEFT(IF(AND(ISNUMBER(G35),G35=T35),"Ahsan, ","")&IF(AND(ISNUMBER(I35),I35=T35),"Aslam, ","")&IF(AND(ISNUMBER(K35),K35=T35),"Jamil, ","")&IF(AND(ISNUMBER(M35),M35=T35),"Muller, ","")&IF(AND(ISNUMBER(O35),O35=T35),"NMMC, ","")&IF(AND(ISNUMBER(Q35),Q35=T35),"Platinum, ",""),LEN(IF(AND(ISNUMBER(G35),G35=T35),"Ahsan, ","")&IF(AND(ISNUMBER(I35),I35=T35),"Aslam, ","")&IF(AND(ISNUMBER(K35),K35=T35),"Jamil, ","")&IF(AND(ISNUMBER(M35),M35=T35),"Muller, ","")&IF(AND(ISNUMBER(O35),O35=T35),"NMMC, ","")&IF(AND(ISNUMBER(Q35),Q35=T35),"Platinum, ",""))-2)) -> NMMC | V35: =IF(S35=0,"",T35*F35) -> 30686
A36: 31 | B36: 99-98-9120026-08-000-000 | C36: OINTMENT-POLYMYXIN-B WITH ZINC BACITRACIN 6G(EYE) | D36: POLYFAX EYE (GSK) | E36: EACH | F36: 200 | K36: 109.96 | L36: POLYFAX EYE OINT | S36: =COUNT(G36,I36,K36,M36,O36,Q36) -> 1 | T36: =IF(S36=0,"",MIN(G36,I36,K36,M36,O36,Q36)) -> 109.96 | U36: =IF(S36=0,"No quote",LEFT(IF(AND(ISNUMBER(G36),G36=T36),"Ahsan, ","")&IF(AND(ISNUMBER(I36),I36=T36),"Aslam, ","")&IF(AND(ISNUMBER(K36),K36=T36),"Jamil, ","")&IF(AND(ISNUMBER(M36),M36=T36),"Muller, ","")&IF(AND(ISNUMBER(O36),O36=T36),"NMMC, ","")&IF(AND(ISNUMBER(Q36),Q36=T36),"Platinum, ",""),LEN(IF(AND(ISNUMBER(G36),G36=T36),"Ahsan, ","")&IF(AND(ISNUMBER(I36),I36=T36),"Aslam, ","")&IF(AND(ISNUMBER(K36),K36=T36),"Jamil, ","")&IF(AND(ISNUMBER(M36),M36=T36),"Muller, ","")&IF(AND(ISNUMBER(O36),O36=T36),"NMMC, ","")&IF(AND(ISNUMBER(Q36),Q36=T36),"Platinum, ",""))-2)) -> Jamil | V36: =IF(S36=0,"",T36*F36) -> 21992
A37: 32 | B37: 99-98-9120019-32-000-000 | C37: TABLET-ALUMINIUM HYDROXIDE COMBINED | D37: WITH MAGNESIUM TRISILICATE, TRISIL(EFROZE), GELUSIL (LCI) | E37: PACKET | F37: 50 | S37: =COUNT(G37,I37,K37,M37,O37,Q37) -> 0 | T37: =IF(S37=0,"",MIN(G37,I37,K37,M37,O37,Q37)) | U37: =IF(S37=0,"No quote",LEFT(IF(AND(ISNUMBER(G37),G37=T37),"Ahsan, ","")&IF(AND(ISNUMBER(I37),I37=T37),"Aslam, ","")&IF(AND(ISNUMBER(K37),K37=T37),"Jamil, ","")&IF(AND(ISNUMBER(M37),M37=T37),"Muller, ","")&IF(AND(ISNUMBER(O37),O37=T37),"NMMC, ","")&IF(AND(ISNUMBER(Q37),Q37=T37),"Platinum, ",""),LEN(IF(AND(ISNUMBER(G37),G37=T37),"Ahsan, ","")&IF(AND(ISNUMBER(I37),I37=T37),"Aslam, ","")&IF(AND(ISNUMBER(K37),K37=T37),"Jamil, ","")&IF(AND(ISNUMBER(M37),M37=T37),"Muller, ","")&IF(AND(ISNUMBER(O37),O37=T37),"NMMC, ","")&IF(AND(ISNUMBER(Q37),Q37=T37),"Platinum, ",""))-2)) -> No quote | V37: =IF(S37=0,"",T37*F37)
A38: 33 | B38: 99-98-9120018-77-000-000 | C38: TABLET-ONDANSETRON 8 MG | D38: UBKINO (ATCO), ONSEGET (GETZ), EMESSON (HIGHNOON), ONDASET (ASPIN), ZOFRAN-AGP (OBS/AGP), ONTIV (SAMI), ADOSETRON (SEARLE), ENDTRON (HORIZON), SEROBLOCK (MARTIN DOW),ONSET (PHARMEDIC) | E38: PACKET | F38: 50 | G38: 335.75 | H38: ONTIV | I38: 382.5 | J38: Horizon | M38: 552.5 | N38: ZOFRAN-AGP (OBS/AGP) | O38: 251.6 | P38: UBKINO 8MG TABLET | S38: =COUNT(G38,I38,K38,M38,O38,Q38) -> 4 | T38: =IF(S38=0,"",MIN(G38,I38,K38,M38,O38,Q38)) -> 251.6 | U38: =IF(S38=0,"No quote",LEFT(IF(AND(ISNUMBER(G38),G38=T38),"Ahsan, ","")&IF(AND(ISNUMBER(I38),I38=T38),"Aslam, ","")&IF(AND(ISNUMBER(K38),K38=T38),"Jamil, ","")&IF(AND(ISNUMBER(M38),M38=T38),"Muller, ","")&IF(AND(ISNUMBER(O38),O38=T38),"NMMC, ","")&IF(AND(ISNUMBER(Q38),Q38=T38),"Platinum, ",""),LEN(IF(AND(ISNUMBER(G38),G38=T38),"Ahsan, ","")&IF(AND(ISNUMBER(I38),I38=T38),"Aslam, ","")&IF(AND(ISNUMBER(K38),K38=T38),"Jamil, ","")&IF(AND(ISNUMBER(M38),M38=T38),"Muller, ","")&IF(AND(ISNUMBER(O38),O38=T38),"NMMC, ","")&IF(AND(ISNUMBER(Q38),Q38=T38),"Platinum, ",""))-2)) -> NMMC | V38: =IF(S38=0,"",T38*F38) -> 12580
A39: 34 | B39: 99-98-9120018-75-000-000 | C39: TABLET-PARACETAMOL WITH ORPHENADRINE | D39: SINAXAMOLEXTRA (OBS/AGP), PROVAS N FORTE (SAMI), NUBEROL FORTE (SEARLE) | E39: PACKET | F39: 500 | G39: 187 | H39: PROVAS N FORTE | I39: 170 | J39: Searle | M39: 262.65 | N39: SINAXAMOLEXTRA (OBS/AGP) | O39: 144.5 | P39: NUBEROL FORTE TABLET | S39: =COUNT(G39,I39,K39,M39,O39,Q39) -> 4 | T39: =IF(S39=0,"",MIN(G39,I39,K39,M39,O39,Q39)) -> 144.5 | U39: =IF(S39=0,"No quote",LEFT(IF(AND(ISNUMBER(G39),G39=T39),"Ahsan, ","")&IF(AND(ISNUMBER(I39),I39=T39),"Aslam, ","")&IF(AND(ISNUMBER(K39),K39=T39),"Jamil, ","")&IF(AND(ISNUMBER(M39),M39=T39),"Muller, ","")&IF(AND(ISNUMBER(O39),O39=T39),"NMMC, ","")&IF(AND(ISNUMBER(Q39),Q39=T39),"Platinum, ",""),LEN(IF(AND(ISNUMBER(G39),G39=T39),"Ahsan, ","")&IF(AND(ISNUMBER(I39),I39=T39),"Aslam, ","")&IF(AND(ISNUMBER(K39),K39=T39),"Jamil, ","")&IF(AND(ISNUMBER(M39),M39=T39),"Muller, ","")&IF(AND(ISNUMBER(O39),O39=T39),"NMMC, ","")&IF(AND(ISNUMBER(Q39),Q39=T39),"Platinum, ",""))-2)) -> NMMC | V39: =IF(S39=0,"",T39*F39) -> 72250
A40: 35 | B40: 99-98-9120018-32-000-000 | C40: TABLET-DIMEMORFAN PHOSPHATE 10 MG | D40: INVENTIVE (AMSON) | E40: PACKET | F40: 50 | S40: =COUNT(G40,I40,K40,M40,O40,Q40) -> 0 | T40: =IF(S40=0,"",MIN(G40,I40,K40,M40,O40,Q40)) | U40: =IF(S40=0,"No quote",LEFT(IF(AND(ISNUMBER(G40),G40=T40),"Ahsan, ","")&IF(AND(ISNUMBER(I40),I40=T40),"Aslam, ","")&IF(AND(ISNUMBER(K40),K40=T40),"Jamil, ","")&IF(AND(ISNUMBER(M40),M40=T40),"Muller, ","")&IF(AND(ISNUMBER(O40),O40=T40),"NMMC, ","")&IF(AND(ISNUMBER(Q40),Q40=T40),"Platinum, ",""),LEN(IF(AND(ISNUMBER(G40),G40=T40),"Ahsan, ","")&IF(AND(ISNUMBER(I40),I40=T40),"Aslam, ","")&IF(AND(ISNUMBER(K40),K40=T40),"Jamil, ","")&IF(AND(ISNUMBER(M40),M40=T40),"Muller, ","")&IF(AND(ISNUMBER(O40),O40=T40),"NMMC, ","")&IF(AND(ISNUMBER(Q40),Q40=T40),"Platinum, ",""))-2)) -> No quote | V40: =IF(S40=0,"",T40*F40)
A41: 36 | B41: 99-98-9120017-42-000-000 | C41: TABLET-RISEDRONATE SODIUM 150 MG | D41: ATCONATE (ATCO) | E41: PACKET | F41: 100 | O41: 493 | P41: ATCONATE 150MG TABLET | S41: =COUNT(G41,I41,K41,M41,O41,Q41) -> 1 | T41: =IF(S41=0,"",MIN(G41,I41,K41,M41,O41,Q41)) -> 493 | U41: =IF(S41=0,"No quote",LEFT(IF(AND(ISNUMBER(G41),G41=T41),"Ahsan, ","")&IF(AND(ISNUMBER(I41),I41=T41),"Aslam, ","")&IF(AND(ISNUMBER(K41),K41=T41),"Jamil, ","")&IF(AND(ISNUMBER(M41),M41=T41),"Muller, ","")&IF(AND(ISNUMBER(O41),O41=T41),"NMMC, ","")&IF(AND(ISNUMBER(Q41),Q41=T41),"Platinum, ",""),LEN(IF(AND(ISNUMBER(G41),G41=T41),"Ahsan, ","")&IF(AND(ISNUMBER(I41),I41=T41),"Aslam, ","")&IF(AND(ISNUMBER(K41),K41=T41),"Jamil, ","")&IF(AND(ISNUMBER(M41),M41=T41),"Muller, ","")&IF(AND(ISNUMBER(O41),O41=T41),"NMMC, ","")&IF(AND(ISNUMBER(Q41),Q41=T41),"Platinum, ",""))-2)) -> NMMC | V41: =IF(S41=0,"",T41*F41) -> 49300
...

Sheet Vendor Summary
A1: VENDOR-WISE SUMMARY
A3: Vendor | B3: Items Quoted | C3: Items at Lowest Rate (L1) | D3: Value of L1 Items
A4: Ahsan | B4: =COUNT(Comparative!G6:G129) -> 45 | C4: =COUNTIF(Comparative!$U$6:$U$129,"*Ahsan*") -> 17 | D4: =SUMIF(Comparative!$U$6:$U$129,"*Ahsan*",Comparative!$V$6:$V$129) -> 592087.5
A5: Aslam | B5: =COUNT(Comparative!I6:I129) -> 40 | C5: =COUNTIF(Comparative!$U$6:$U$129,"*Aslam*") -> 15 | D5: =SUMIF(Comparative!$U$6:$U$129,"*Aslam*",Comparative!$V$6:$V$129) -> 626325.5
A6: Jamil | B6: =COUNT(Comparative!K6:K129) -> 33 | C6: =COUNTIF(Comparative!$U$6:$U$129,"*Jamil*") -> 12 | D6: =SUMIF(Comparative!$U$6:$U$129,"*Jamil*",Comparative!$V$6:$V$129) -> 771799.6
A7: Muller | B7: =COUNT(Comparative!M6:M129) -> 56 | C7: =COUNTIF(Comparative!$U$6:$U$129,"*Muller*") -> 17 | D7: =SUMIF(Comparative!$U$6:$U$129,"*Muller*",Comparative!$V$6:$V$129) -> 3002991
A8: NMMC | B8: =COUNT(Comparative!O6:O129) -> 68 | C8: =COUNTIF(Comparative!$U$6:$U$129,"*NMMC*") -> 51 | D8: =SUMIF(Comparative!$U$6:$U$129,"*NMMC*",Comparative!$V$6:$V$129) -> 3686576
A9: Platinum | B9: =COUNT(Comparative!Q6:Q129) -> 8 | C9: =COUNTIF(Comparative!$U$6:$U$129,"*Platinum*") -> 6 | D9: =SUMIF(Comparative!$U$6:$U$129,"*Platinum*",Comparative!$V$6:$V$129) -> 277219.25
A10: Items with no quote | C10: =COUNTIF(Comparative!$U$6:$U$129,"No quote") -> 10
A11: Total items in RFQ | C11: =COUNTA(Comparative!B6:B129) -> 124
A13: Notes:
A14: 1. Where two or more vendors quote the same lowest rate (tie), all are shown and each is counted as L1 above.
A15: 2. Aslam quoted company/manufacturer names (e.g. Bosch, Searle, Haleon) instead of brand names, and gave no totals.
A16: 3. Some vendors stated pack sizes in remarks (e.g. Aslam "6's", "14's") – confirm pack size matches the UOM before award.
A17: 4. NMMC "NIL" and Platinum "NA" entries are treated as not quoted.
A18: 5. Source: vendor RFQ files Ahsan.xls, Aslam.xls, Jamil.xls, Muller.xls, NMMC.xls, Platinum.xls (rates entered as received).
A19: 6. Aslam_2.xls was checked cell by cell and is identical to Aslam.xls (same rates, brands, remarks), so it is not shown as a separate vendor.
